Workbook

Sheet Raw Data
A1: County | B1: 2019_Area(Ha) | C1: 2019_Production(Tonnes) | D1: 2020_Area(Ha) | E1: 2020_Production(Tons) | F1: 2021_Area(Ha) | G1: 2021_Production(Tons) | H1: 2022_Area(Ha) | I1: 2022_Production(Tons) | J1: 2023_Area(Ha) | K1: 2023_Production(Tons) | L1: 2024_Area(Ha) | M1: 2024_Production(Tons)
A2: Baringo | B2: 45171 | C2: 70810 | D2: 47437 | E2: 68374 | F2: 34709 | G2: 59169 | H2: 37894 | I2: 50820 | J2: 42501 | K2: 94877 | L2: 47457 | M2: 83958
A3: Bomet | B3: 34476 | C3: 74728 | D3: 42763 | E3: 73610 | F3: 40480 | G3: 58685 | H3: 27597 | I3: 43387 | J3: 27250 | K3: 63230 | L3: 33491 | M3: 52714
A4: Bungoma | B4: 94635 | C4: 315711 | D4: 87960 | E4: 317912 | F4: 93214 | G4: 269443 | H4: 92464 | I4: 275420 | J4: 92847 | K4: 222912 | L4: 90297 | M4: 207846
A5: Busia | B5: 61850 | C5: 67445 | D5: 48150 | E5: 69450 | F5: 33810 | G5: 42028 | H5: 42476 | I5: 64360 | J5: 44097 | K5: 71237 | L5: 44204 | M5: 77934
A6: Elgeyo Marakwet | B6: 31779 | C6: 104487 | D6: 25856 | E6: 87431 | F6: 31351 | G6: 86007 | H6: 31713 | I6: 72330 | J6: 43133 | K6: 150221 | L6: 42182 | M6: 117786
A7: Embu | B7: 34100 | C7: 28368 | D7: 35130 | E7: 34650 | F7: 35925 | G7: 31378 | H7: 34506 | I7: 10077 | J7: 34500 | K7: 41327 | L7: 34750 | M7: 25659
A8: Garissa | B8: 150 | C8: 109 | D8: 238 | E8: 296 | F8: 145 | G8: 71 | H8: 107 | I8: 70 | J8: 142 | K8: 132 | L8: 222 | M8: 382
A9: Homa Bay | B9: 72793 | C9: 102742 | D9: 72097 | E9: 92394 | F9: 79608 | G9: 82278 | H9: 72215 | I9: 86658 | J9: 78795 | K9: 115635 | L9: 89172 | M9: 146866
A10: Isiolo | B10: 530 | C10: 749 | D10: 586 | E10: 42 | F10: 147 | G10: 139 | H10: 129 | I10: 94 | J10: 256 | K10: 176 | L10: 288 | M10: 576
A11: Kajiado | B11: 17511 | C11: 16189 | D11: 31384 | E11: 15543 | F11: 4808 | G11: 2864 | H11: 32159 | I11: 13063 | J11: 33241 | K11: 40733 | L11: 21906 | M11: 40573
A12: Kakamega | B12: 95390 | C12: 259003 | D12: 83773 | E12: 226888 | F12: 98415 | G12: 262506 | H12: 100641 | I12: 154369 | J12: 87532 | K12: 132572 | L12: 105181 | M12: 212753
A13: Kericho | B13: 32050 | C13: 85815 | D13: 34397 | E13: 92731 | F13: 35068 | G13: 98746 | H13: 40530 | I13: 85975 | J13: 40643 | K13: 111130 | L13: 43908 | M13: 134358
... A48: West Pokot | B48: 36720 | C48: 82849 | D48: 32354 | E48: 23400 | F48: 34911 | G48: 53193 | H48: 34780 | I48: 52650 | J48: 49097 | K48: 96010 | L48: 56403 | M48: 96984

Sheet Normalized Indicators
A1: County | B1: Year | C1: Indicator | D1: Value
A2: Baringo | B2: 2019 | C2: Area (HA) | D2: ='Raw Data'!B2 -> 45171
A3: Baringo | B3: 2019 | C3: Production (MT) | D3: ='Raw Data'!C2 -> 70810
A4: Baringo | B4: 2019 | C4: Yield(MT/HA) | D4: =IF('Raw Data'!B2>0, 'Raw Data'!C2/'Raw Data'!B2, 0) -> 1.5675987
A5: Baringo | B5: 2020 | C5: Area (HA) | D5: ='Raw Data'!D2 -> 47437
A6: Baringo | B6: 2020 | C6: Production (MT) | D6: ='Raw Data'!E2 -> 68374
A7: Baringo | B7: 2020 | C7: Yield(MT/HA) | D7: =IF('Raw Data'!D2>0, 'Raw Data'!E2/'Raw Data'!D2, 0) -> 1.4413643
A8: Baringo | B8: 2021 | C8: Area (HA) | D8: ='Raw Data'!F2 -> 34709
A9: Baringo | B9: 2021 | C9: Production (MT) | D9: ='Raw Data'!G2 -> 59169
A10: Baringo | B10: 2021 | C10: Yield(MT/HA) | D10: =IF('Raw Data'!F2>0, 'Raw Data'!G2/'Raw Data'!F2, 0) -> 1.7047164
A11: Baringo | B11: 2022 | C11: Area (HA) | D11: ='Raw Data'!H2 -> 37894
A12: Baringo | B12: 2022 | C12: Production (MT) | D12: ='Raw Data'!I2 -> 50820
A13: Baringo | B13: 2022 | C13: Yield(MT/HA) | D13: =IF('Raw Data'!H2>0, 'Raw Data'!I2/'Raw Data'!H2, 0) -> 1.3411094
A14: Baringo | B14: 2023 | C14: Area (HA) | D14: ='Raw Data'!J2 -> 42501
A15: Baringo | B15: 2023 | C15: Production (MT) | D15: ='Raw Data'!K2 -> 94877
A16: Baringo | B16: 2023 | C16: Yield(MT/HA) | D16: =IF('Raw Data'!J2>0, 'Raw Data'!K2/'Raw Data'!J2, 0) -> 2.2323475
A17: Baringo | B17: 2024 | C17: Area (HA) | D17: ='Raw Data'!L2 -> 47457
A18: Baringo | B18: 2024 | C18: Production (MT) | D18: ='Raw Data'!M2 -> 83958
A19: Baringo | B19: 2024 | C19: Yield(MT/HA) | D19: =IF('Raw Data'!L2>0, 'Raw Data'!M2/'Raw Data'!L2, 0) -> 1.7691384
A20: Bomet | B20: 2019 | C20: Area (HA) | D20: ='Raw Data'!B3 -> 34476
A21: Bomet | B21: 2019 | C21: Production (MT) | D21: ='Raw Data'!C3 -> 74728
A22: Bomet | B22: 2019 | C22: Yield(MT/HA) | D22: =IF('Raw Data'!B3>0, 'Raw Data'!C3/'Raw Data'!B3, 0) -> 2.1675368
A23: Bomet | B23: 2020 | C23: Area (HA) | D23: ='Raw Data'!D3 -> 42763
A24: Bomet | B24: 2020 | C24: Production (MT) | D24: ='Raw Data'!E3 -> 73610
A25: Bomet | B25: 2020 | C25: Yield(MT/HA) | D25: =IF('Raw Data'!D3>0, 'Raw Data'!E3/'Raw Data'!D3, 0) -> 1.7213479
A26: Bomet | B26: 2021 | C26: Area (HA) | D26: ='Raw Data'!F3 -> 40480
A27: Bomet | B27: 2021 | C27: Production (MT) | D27: ='Raw Data'!G3 -> 58685
A28: Bomet | B28: 2021 | C28: Yield(MT/HA) | D28: =IF('Raw Data'!F3>0, 'Raw Data'!G3/'Raw Data'!F3, 0) -> 1.4497283
A29: Bomet | B29: 2022 | C29: Area (HA) | D29: ='Raw Data'!H3 -> 27597
A30: Bomet | B30: 2022 | C30: Production (MT) | D30: ='Raw Data'!I3 -> 43387
A31: Bomet | B31: 2022 | C31: Yield(MT/HA) | D31: =IF('Raw Data'!H3>0, 'Raw Data'!I3/'Raw Data'!H3, 0) -> 1.5721636
A32: Bomet | B32: 2023 | C32: Area (HA) | D32: ='Raw Data'!J3 -> 27250
A33: Bomet | B33: 2023 | C33: Production (MT) | D33: ='Raw Data'!K3 -> 63230
A34: Bomet | B34: 2023 | C34: Yield(MT/HA) | D34: =IF('Raw Data'!J3>0, 'Raw Data'!K3/'Raw Data'!J3, 0) -> 2.320367
A35: Bomet | B35: 2024 | C35: Area (HA) | D35: ='Raw Data'!L3 -> 33491
A36: Bomet | B36: 2024 | C36: Production (MT) | D36: ='Raw Data'!M3 -> 52714
A37: Bomet | B37: 2024 | C37: Yield(MT/HA) | D37: =IF('Raw Data'!L3>0, 'Raw Data'!M3/'Raw Data'!L3, 0) -> 1.5739751
A38: Bungoma | B38: 2019 | C38: Area (HA) | D38: ='Raw Data'!B4 -> 94635
A39: Bungoma | B39: 2019 | C39: Production (MT) | D39: ='Raw Data'!C4 -> 315711
A40: Bungoma | B40: 2019 | C40: Yield(MT/HA) | D40: =IF('Raw Data'!B4>0, 'Raw Data'!C4/'Raw Data'!B4, 0) -> 3.3360913
...
